Workbook

Sheet Artikli
A1: Št. | B1: Opis | C1: Zaloga | D1: Obstajajo nadomestki | E1: Kosovnica sestavljanja | F1: Št. proizvodne kosovnice | G1: Knjižna skupina zaloge | H1: Št. proizvodnega postopka | I1: Osnovna merska enota | J1: Strošek je popravljen | K1: Strošek enote | L1: Cena enote | M1: Carinska tarifa | N1: Št. dobavitelja | O1: Sistem dopolnitve zalog | P1: Način knjiženja porabe | Q1: Privzeta predloga odloga
A2: 000001 | B2: L-GLUTAMINE (VEGAN) 88017 (FRUTOL) | C2: 0 | D2: =TRUE() -> TRUE | E2: =FALSE() -> FALSE | G2: MATERIAL | I2: KG | J2: =TRUE() -> TRUE | K2: 0 | L2: 0 | M2: 2924190090 | N2: 0001 | O2: Nabava | P2: Ročno
A3: 000002 | B3: L-Arginine hydrochloride [vegan] RM079-A (Vita Actives) | C3: 0 | D3: =TRUE() -> TRUE | E3: =FALSE() -> FALSE | G3: MATERIAL | I3: KG | J3: =TRUE() -> TRUE | K3: 8.75 | L3: 8.75 | M3: 2925290090 | N3: 0002 | O3: Nabava | P3: Ročno
A4: 000003 | B4: L-Lysine HCL (HSH) | C4: 12.5 | D4: =TRUE() -> TRUE | E4: =FALSE() -> FALSE | G4: MATERIAL | I4: KG | J4: =TRUE() -> TRUE | K4: 3.4 | L4: 0 | M4: 2922419929 | N4: 0003 | O4: Nabava | P4: Ročno
A5: 000004 | B5: L-Taurine A0226 (Pharmavit) | C5: 202.525 | D5: =FALSE() -> FALSE | E5: =FALSE() -> FALSE | G5: MATERIAL | I5: KG | J5: =FALSE() -> FALSE | K5: 2.95002 | L5: 2.95 | M5: 29239000 | N5: 0004 | O5: Nabava | P5: Ročno
A6: 000005 | B6: Megaflora 9, Powder EVO (HSH) | C6: 135 | D6: =FALSE() -> FALSE | E6: =FALSE() -> FALSE | G6: MATERIAL | I6: KG | J6: =FALSE() -> FALSE | K6: 97.5 | L6: 87.5 | M6: 21069098 | N6: 0003 | O6: Nabava | P6: Ročno
A7: 000006 | B7: Glycine powder RM063-A (Vita Actives) | C7: 0 | D7: =TRUE() -> TRUE | E7: =FALSE() -> FALSE | G7: MATERIAL | I7: KG | J7: =TRUE() -> TRUE | K7: 0 | L7: 0 | M7: 2922498517 | N7: 0002 | O7: Nabava | P7: Ročno
A8: 000007 | B8: Magnesium citrate anhydrous (HSH) | C8: 13.5 | D8: =TRUE() -> TRUE | E8: =FALSE() -> FALSE | G8: MATERIAL | I8: KG | J8: =TRUE() -> TRUE | K8: 6.84963 | L8: 6.85 | M8: 2918150090 | N8: 0003 | O8: Nabava | P8: Ročno
A9: 000008 | B9: L-Methionine [vegan] (Gonmisol) | C9: 0 | D9: =TRUE() -> TRUE | E9: =FALSE() -> FALSE | G9: MATERIAL | I9: KG | J9: =TRUE() -> TRUE | K9: 0 | L9: 0 | M9: 29304010 | N9: 0007 | O9: Nabava | P9: Ročno
A10: 000009 | B10: DOG ROSE FRUIT EXTRACT 70% 88022 (FRUTOL) | C10: 0 | D10: =TRUE() -> TRUE | E10: =FALSE() -> FALSE | G10: MATERIAL | I10: KG | J10: =TRUE() -> TRUE | K10: 0 | L10: 0 | M10: 1302197000 | N10: 0001 | O10: Nabava | P10: Ročno
A11: 000010 | B11: Maltodextrin (VitaActives)RM311-C | C11: 100.675 | D11: =TRUE() -> TRUE | E11: =FALSE() -> FALSE | G11: MATERIAL | I11: KG | J11: =FALSE() -> FALSE | K11: 1.49999 | L11: 0 | M11: 17029050 | N11: 0008 | O11: Nabava | P11: Ročno
A12: 000011 | B12: AKRAROM LEMON FRUIT POWDER 75600142 (FRUTOL) | C12: 62.60612 | D12: =TRUE() -> TRUE | E12: =FALSE() -> FALSE | G12: MATERIAL | I12: KG | J12: =FALSE() -> FALSE | K12: 18.50017 | L12: 0 | M12: 21069098 | N12: 0023 | O12: Nabava | P12: Ročno
A13: 000012 | B13: L-Cysteine HCl monohydrate (HSH Chemie) | C13: 28.22569 | D13: =TRUE() -> TRUE | E13: =FALSE() -> FALSE | G13: MATERIAL | I13: KG | J13: =FALSE() -> FALSE | K13: 11.5001 | L13: 0 | M13: 2930901300 | N13: 0003 | O13: Nabava | P13: Ročno
A14: 000013 | B14: MULTIVITAMIN PREMIX FUNCTIONAL 88001 (FRUTOL) | C14: 0 | D14: =FALSE() -> FALSE | E14: =FALSE() -> FALSE | G14: MATERIAL | I14: KG | J14: =TRUE() -> TRUE | K14: 0 | L14: 0 | M14: 29369000 | N14: 0001 | O14: Nabava | P14: Ročno
A15: 000014 | B15: Zinc gluconate A0239 Pharmavit | C15: 10.40014 | D15: =FALSE() -> FALSE | E15: =FALSE() -> FALSE | G15: MATERIAL | I15: KG | J15: =FALSE() -> FALSE | K15: 7.94994 | L15: 0 | M15: 29181600 | N15: 0002 | O15: Nabava | P15: Ročno
A16: 000015 | B16: Selenium enriched yeast (HSH) | C16: 32.82083 | D16: =FALSE() -> FALSE | E16: =FALSE() -> FALSE | G16: MATERIAL | I16: KG | J16: =FALSE() -> FALSE | K16: 31.74997 | L16: 0 | M16: 21022090 | N16: 0003 | O16: Nabava | P16: Ročno
A17: 000016 | B17: Copper citrate (HSH) | C17: 0.51512 | D17: =FALSE() -> FALSE | E17: =FALSE() -> FALSE | G17: MATERIAL | I17: KG | J17: =FALSE() -> FALSE | K17: 220.00411 | L17: 0 | M17: 2918160090 | N17: 0003 | O17: Nabava | P17: Ročno
A18: 000017 | B18: ORANGE-FLAVOUR SD 221524 (FRUTOL) | C18: 93.62103 | D18: =FALSE() -> FALSE | E18: =FALSE() -> FALSE | G18: MATERIAL | I18: KG | J18: =FALSE() -> FALSE | K18: 18 | L18: 0 | M18: 3302109000 | N18: 0023 | O18: Nabava | P18: Ročno
A19: 000018 | B19: TANGERINE-FLAVOUR SD 01650028 (FRUTOL) | C19: 2.60566 | D19: =FALSE() -> FALSE | E19: =FALSE() -> FALSE | G19: MATERIAL | I19: KG | J19: =FALSE() -> FALSE | K19: 34.3001 | L19: 0 | M19: 33021090 | N19: 0001 | O19: Nabava | P19: Ročno
A20: 000019 | B20: LEMON-FLAVOUR SD 221589 (FRUTOL) | C20: 70.4982 | D20: =FALSE() -> FALSE | E20: =FALSE() -> FALSE | G20: MATERIAL | I20: KG | J20: =FALSE() -> FALSE | K20: 21 | L20: 0 | M20: 3302109000 | N20: 0001 | O20: Nabava | P20: Ročno
A21: 000020 | B21: Inka Sweet Stevia Phí (Inka Sweet) | C21: 29.4996 | D21: =FALSE() -> FALSE | E21: =FALSE() -> FALSE | G21: MATERIAL | I21: KG | J21: =FALSE() -> FALSE | K21: 104.14516 | L21: 0 | M21: 2106909849 | N21: 0011 | O21: Nabava | P21: Ročno
A22: 000021 | B22: S-AEROSIL 200F (Sensilab) | C22: 3.07458 | D22: =FALSE() -> FALSE | E22: =FALSE() -> FALSE | G22: MATERIAL | I22: KG | J22: =TRUE() -> TRUE | K22: 17.3292 | L22: 17.33 | M22: 28112200 | N22: 0062 | O22: Nabava | P22: Ročno
A23: 000022 | B23: L-Cysteine HCl monohydrate [vegan] RM740 (Vita Actives) | C23: 25 | D23: =TRUE() -> TRUE | E23: =FALSE() -> FALSE | G23: MATERIAL | I23: KG | J23: =FALSE() -> FALSE | K23: 11.5 | L23: 0 | M23: 2930901300 | N23: 0003 | O23: Nabava | P23: Ročno
A24: 000023 | B24: L-LYSINE HCL 88079 (FRUTOL) | C24: 0 | D24: =TRUE() -> TRUE | E24: =FALSE() -> FALSE | G24: MATERIAL | I24: KG | J24: =TRUE() -> TRUE | K24: 0 | L24: 0 | M24: 2922410020 | N24: 0001 | O24: Nabava | P24: Ročno
A25: 000024 | B25: Magnesium Citrate Tribasic anhydrous RM450 (Vita Actives) RM450 | C25: 7.9375 | D25: =TRUE() -> TRUE | E25: =FALSE() -> FALSE | G25: MATERIAL | I25: KG | J25: =TRUE() -> TRUE | K25: 7.81984 | L25: 7.82 | M25: 291850090 | N25: 0002 | O25: Nabava | P25: Ročno
A26: 000025 | B26: B-Complex Capsule Premix PRM101 (VitaActives) | C26: 50 | D26: =FALSE() -> FALSE | E26: =FALSE() -> FALSE | G26: MATERIAL | I26: KG | J26: =FALSE() -> FALSE | K26: 40 | L26: 40 | M26: 29369000 | N26: 0002 | O26: Nabava | P26: Ročno
A27: 000026 | B27: Rose hip dry extract RM4037 (VitaActives) | C27: 0 | D27: =TRUE() -> TRUE | E27: =FALSE() -> FALSE | G27: MATERIAL | I27: KG | J27: =TRUE() -> TRUE | K27: 41.99999 | L27: 0 | M27: 13021970 00 | N27: 0015 | O27: Nabava | P27: Ročno
A28: 000027 | B28: Lemon Powder Organic PFI500414 (Nexira) | C28: 0 | D28: =TRUE() -> TRUE | E28: =FALSE() -> FALSE | G28: MATERIAL | I28: KG | J28: =TRUE() -> TRUE | K28: 0 | L28: 0 | M28: 21069092 | N28: 0016 | O28: Nabava | P28: Ročno
A29: 000028 | B29: L-CYSTEINE HCL MONOHYDRATE 88088 (FRUTOL) | C29: 0 | D29: =TRUE() -> TRUE | E29: =FALSE() -> FALSE | G29: MATERIAL | I29: KG | J29: =TRUE() -> TRUE | K29: 0 | L29: 0 | M29: 2930901300 | N29: 0001 | O29: Nabava | P29: Ročno
A30: 000029 | B30: Riboflavin powder [Vitamin B2] | C30: 0 | D30: =FALSE() -> FALSE | E30: =FALSE() -> FALSE | G30: MATERIAL | I30: KG | J30: =TRUE() -> TRUE | K30: 0 | L30: 0 | O30: Nabava | P30: Ročno
A31: 000030 | B31: Magnesium Carbonate Heavy Powder (Vita Actives)RM1372-A | C31: 130 | D31: =FALSE() -> FALSE | E31: =FALSE() -> FALSE | G31: MATERIAL | I31: KG | J31: =FALSE() -> FALSE | K31: 6.6 | L31: 0 | M31: 28365000 | N31: 0002 | O31: Nabava | P31: Ročno
A32: 000031 | B32: Nicotinamide [Vitamin B3] | C32: 0 | D32: =FALSE() -> FALSE | E32: =FALSE() -> FALSE | G32: MATERIAL | I32: KG | J32: =TRUE() -> TRUE | K32: 0 | L32: 0 | M32: 29362900 | O32: Nabava | P32: Ročno
A33: 000032 | B33: Magnesium Stearate [Vegetable] (Vita Actives)RM465 | C33: 449.775 | D33: =TRUE() -> TRUE | E33: =FALSE() -> FALSE | G33: MATERIAL | I33: KG | J33: =FALSE() -> FALSE | K33: 4.14 | L33: 0 | M33: 29157050 | N33: 0002 | O33: Nabava | P33: Ročno
A34: 000033 | B34: BETA-ALANINE [VEGAN](Vita Actives) RM007B | C34: 20 | D34: =TRUE() -> TRUE | E34: =FALSE() -> FALSE | G34: MATERIAL | I34: KG | J34: =TRUE() -> TRUE | K34: 2.94 | L34: 0 | M34: 2922498590 | N34: 0002 | O34: Nabava | P34: Ročno
A35: 000034 | B35: D-RIBOSE (Vita Actives) RM056 | C35: 104.86 | D35: =FALSE() -> FALSE | E35: =FALSE() -> FALSE | G35: MATERIAL | I35: KG | J35: =FALSE() -> FALSE | K35: 13.34025 | L35: 0 | M35: 2940000080 | N35: 0002 | O35: Nabava | P35: Ročno
A36: 000035 | B36: RHODIOLA DE 3% ROSAVINS 1% SALIDROSIDE (Vita Actives) RM461 | C36: 283.18 | D36: =TRUE() -> TRUE | E36: =FALSE() -> FALSE | G36: MATERIAL | I36: KG | J36: =FALSE() -> FALSE | K36: 184 | L36: 0 | M36: 1302197000 | N36: 0002 | O36: Nabava | P36: Ročno
A37: 000036 | B37: KSM-66® [Ashwagandha extract] RM1236 | C37: 112 | D37: =FALSE() -> FALSE | E37: =FALSE() -> FALSE | G37: MATERIAL | I37: KG | J37: =FALSE() -> FALSE | K37: 74.5 | L37: 0 | M37: 1302197000 | N37: 0002 | O37: Nabava | P37: Ročno
A38: 000037 | B38: CrPIX® [Chromium picolinate] RM022-A (pazi količino) | C38: 4160 | D38: =FALSE() -> FALSE | E38: =FALSE() -> FALSE | G38: MATERIAL | I38: GR | J38: =TRUE() -> TRUE | K38: 0.17 | L38: 0 | M38: 2819909090 | N38: 0002 | O38: Nabava | P38: Ročno
A39: 000038 | B39: GUSTOSAL evap. jedilna sol, nejod., fina, (Salinen) | C39: 6200.9351 | D39: =FALSE() -> FALSE | E39: =FALSE() -> FALSE | G39: MATERIAL | I39: KG | J39: =FALSE() -> FALSE | K39: 0.265 | L39: 0 | M39: 25010091 | N39: 0075 | O39: Nabava | P39: Ročno
A40: 000039 | B40: Calcium citrate Tetrahydrate (Vita Actives) RM018-B | C40: 136.19984 | D40: =TRUE() -> TRUE | E40: =FALSE() -> FALSE | G40: MATERIAL | I40: KG | J40: =FALSE() -> FALSE | K40: 4.26966 | L40: 0 | M40: 29181500 | N40: 0002 | O40: Nabava | P40: Ročno
...

Sheet Nadomeščanje artikla
A1: JJ-POSAMEZNO | B1: Nadomeščanje artikla | C1: 5715
A3: Vrsta | B3: Št. | C3: Šifra različice | D3: Vrsta nadomestka | E3: Št. nadomestka | F3: Šifra različice nadomestka | G3: Opis | H3: Zaloga | I3: Izmenljivo | J3: Nivo odnosov | K3: Količina na voljo na datum dobave | L3: Datum dobave
A4: Artikel | B4: 000001 | D4: Artikel | E4: 000113 | G4: A1101 AMINOFERMENT® L-Glutamin (Pharmavit) | H4: 0 | I4: true | J4: 0 | K4: 0
A5: Artikel | B5: 000001 | D5: Artikel | E5: 000123 | G5: L-Glutamine (Vegan) BIOSTILE | H5: 0 | I5: true | J5: 0 | K5: 0
A6: Artikel | B6: 000002 | D6: Artikel | E6: 000089 | G6: AMINOFERMENT® L-Arginin HCL A0147_B (pharmavit) | H6: 0 | I6: true | J6: 0 | K6: 0
A7: Artikel | B7: 000003 | D7: Artikel | E7: 000023 | G7: L-LYSINE HCL 88079 (FRUTOL) | H7: 0 | I7: true | J7: 0 | K7: 0
A8: Artikel | B8: 000003 | D8: Artikel | E8: 000114 | G8: A0876 AMINOFERMENT® L-Lysin HCL (Pharmavit) | H8: 0 | I8: true | J8: 0 | K8: 0
A9: Artikel | B9: 000006 | D9: Artikel | E9: 000090 | G9: L-Glycine (HSH) | H9: 0 | I9: false | J9: 0 | K9: 0
A10: Artikel | B10: 000006 | D10: Artikel | E10: 000124 | G10: A0552 AMINOFERMENT® L-Glycin (Pharmavit) | H10: 0 | I10: true | J10: 0 | K10: 0
A11: Artikel | B11: 000007 | D11: Artikel | E11: 000024 | G11: Magnesium Citrate Tribasic anhydrous (Vita Actives) RM450 | H11: 0 | I11: true | J11: 0 | K11: 0
A12: Artikel | B12: 000007 | D12: Artikel | E12: 000106 | G12: A0477 Magnesium Citrate Anhydrous DC (Pharmavit) | H12: 0 | I12: true | J12: 0 | K12: 0
A13: Artikel | B13: 000007 | D13: Artikel | E13: 000118 | G13: Magnesium citrate anhydrous A0729 (Pharmavit) | H13: 0 | I13: true | J13: 0 | K13: 0
A14: Artikel | B14: 000008 | D14: Artikel | E14: 000115 | G14: A1109 AMINOFERMENT® L-Methionin (Pharmavit) | H14: 0 | I14: true | J14: 0 | K14: 0
A15: Artikel | B15: 000009 | D15: Artikel | E15: 000026 | G15: Rose hip dry extract PR2075 | H15: 0 | I15: true | J15: 0 | K15: 0
... A116: Artikel | B116: 300024 | D116: Artikel | E116: 300006 | G116: POK Closure metal gold SP 38/400 IHS Obeck | H116: 0 | I116: true | J116: 0 | K116: 0

Sheet List1
A3: Oznake vrstic | B3: Vsota od Količina
A4: 000002
A5: L-Arginine hydrochloride [vegan] RM079-A (Vita Actives) | B5: 525
A6: 000024
A7: Magnesium Citrate Tribasic anhydrous RM450 (Vita Actives) RM450 | B7: 400
A8: 000025
A9: B-Complex Capsule Premix PRM101 (VitaActives) | B9: 40
A10: 000030
A11: Magnesium Carbonate Heavy Powder (Vita Actives)RM1372-A | B11: 360
A12: 000032
A13: Magnesium Stearate [Vegetable] (Vita Actives)RM465 | B13: 500
A14: 000034
A15: D-RIBOSE (Vita Actives) RM056 | B15: 75
A16: 000035
A17: RHODIOLA DE 3% ROSAVINS 1% SALIDROSIDE (Vita Actives) RM461 | B17: 275
A18: 000036
A19: KSM-66® [Ashwagandha extract] RM1236 | B19: 30
A20: 000047
A21: TeaXcel® E40 - Green tea leaf 95% polyphenols RM303 | B21: 450
A22: 000049
A23: CAYENNE PEPER 10:1 (Vita Actives) RM4766 | B23: 100
A24: 000051
A25: Grape Seed Extract GSE (Vita Actives) RM4160 | B25: 100
A26: 000053
A27: Caffeine Anhydrous powder (Vita Actives) RM017 | B27: 50
A28: 000055
A29: Magnesium Oxide DC Granular RM118B (Vita Actives) | B29: 1500
A30: 000056
A31: Isomaltulose Powder RM1501 (Vita Actives) | B31: 25
A32: 000060
A33: Citric Acid Anhydrous (Pharmavit) | B33: 50
A34: 000061
A35: Calcium pyruvate powder RM730 (VitaActives) | B35: 75
A36: 000063
A37: GINSENG EXTRACT 80% RM 713 (VitaActives) | B37: 25
A38: 000068
A39: 00123 Cordyceps 7% Cordiceptic Acid extract powder (Alpine Nutrition) | B39: 10
A40: 000071
A41: Creatine HCL hydrochloride RM 032 (VitaActives) | B41: 900
A42: 000072
...

Sheet Delovni listi načrtovanja
A1: Ime | B1: Opozorilo | C1: Št. | D1: Sporočilo o dejanju | E1: Sprejmi sporočilo o dejanju | F1: Prvotni datum zapadlosti | G1: Datum naloga | H1: Datum zapadlosti | I1: Končni datum | J1: Opis | K1: Št. proizvodne kosovnice | L1: Prvotna količina | M1: Nalog MPS | N1: Količina | O1: Vrsta referenčnega naloga | P1: Št. dobavitelja | Q1: ItemDescription | R1: Opis proizvodnega postopka
A2: JANEZ-MRP | C2: 000002 | D2: Novo | E2: =FALSE() -> FALSE | G2: 46322 | H2: 46352 | I2: 46352 | J2: L-Arginine hydrochloride [vegan] RM079-A (Vita Actives) | L2: 0 | M2: =FALSE() -> FALSE | N2: 525 | O2: Nabava | P2: 0002 | Q2: L-Arginine hydrochloride [vegan] RM079-A (Vita Actives)
A3: JANEZ-MRP | B3: Attention | C3: 000024 | D3: Novo | E3: =FALSE() -> FALSE | G3: 46116 | H3: 46146 | I3: 46146 | J3: Magnesium Citrate Tribasic anhydrous RM450 (Vita Actives) RM450 | L3: 0 | M3: =FALSE() -> FALSE | N3: 100 | O3: Nabava | P3: 0002 | Q3: Magnesium Citrate Tribasic anhydrous RM450 (Vita Actives) RM450
A4: JANEZ-MRP | C4: 000024 | D4: Novo | E4: =TRUE() -> TRUE | G4: 46307 | H4: 46337 | I4: 46337 | J4: Magnesium Citrate Tribasic anhydrous RM450 (Vita Actives) RM450 | L4: 0 | M4: =FALSE() -> FALSE | N4: 100 | O4: Nabava | P4: 0002 | Q4: Magnesium Citrate Tribasic anhydrous RM450 (Vita Actives) RM450
A5: JANEZ-MRP | C5: 000024 | D5: Novo | E5: =TRUE() -> TRUE | G5: 46307 | H5: 46337 | I5: 46337 | J5: Magnesium Citrate Tribasic anhydrous RM450 (Vita Actives) RM450 | L5: 0 | M5: =FALSE() -> FALSE | N5: 100 | O5: Nabava | P5: 0002 | Q5: Magnesium Citrate Tribasic anhydrous RM450 (Vita Actives) RM450
A6: JANEZ-MRP | C6: 000024 | D6: Novo | E6: =TRUE() -> TRUE | G6: 46307 | H6: 46337 | I6: 46337 | J6: Magnesium Citrate Tribasic anhydrous RM450 (Vita Actives) RM450 | L6: 0 | M6: =FALSE() -> FALSE | N6: 100 | O6: Nabava | P6: 0002 | Q6: Magnesium Citrate Tribasic anhydrous RM450 (Vita Actives) RM450
A7: JANEZ-MRP | C7: 000025 | D7: Novo | E7: =TRUE() -> TRUE | G7: 46140 | H7: 46170 | I7: 46170 | J7: B-Complex Capsule Premix PRM101 (VitaActives) | L7: 0 | M7: =FALSE() -> FALSE | N7: 40 | O7: Nabava | P7: 0002 | Q7: B-Complex Capsule Premix PRM101 (VitaActives)
A8: JANEZ-MRP | C8: 000030 | D8: Novo | E8: =TRUE() -> TRUE | G8: 46307 | H8: 46337 | I8: 46337 | J8: Magnesium Carbonate Heavy Powder (Vita Actives)RM1372-A | L8: 0 | M8: =FALSE() -> FALSE | N8: 360 | O8: Nabava | P8: 0002 | Q8: Magnesium Carbonate Heavy Powder (Vita Actives)RM1372-A
A9: JANEZ-MRP | C9: 000032 | D9: Novo | E9: =TRUE() -> TRUE | G9: 46348 | H9: 46378 | I9: 46378 | J9: Magnesium Stearate [Vegetable] (Vita Actives)RM465 | L9: 0 | M9: =FALSE() -> FALSE | N9: 500 | O9: Nabava | P9: 0002 | Q9: Magnesium Stearate [Vegetable] (Vita Actives)RM465
A10: JANEZ-MRP | C10: 000034 | D10: Novo | E10: =TRUE() -> TRUE | G10: 46347 | H10: 46377 | I10: 46377 | J10: D-RIBOSE (Vita Actives) RM056 | L10: 0 | M10: =FALSE() -> FALSE | N10: 75 | O10: Nabava | P10: 0002 | Q10: D-RIBOSE (Vita Actives) RM056
A11: JANEZ-MRP | C11: 000035 | D11: Novo | E11: =TRUE() -> TRUE | G11: 46328 | H11: 46358 | I11: 46358 | J11: RHODIOLA DE 3% ROSAVINS 1% SALIDROSIDE (Vita Actives) RM461 | L11: 0 | M11: =FALSE() -> FALSE | N11: 200 | O11: Nabava | P11: 0002 | Q11: RHODIOLA DE 3% ROSAVINS 1% SALIDROSIDE (Vita Actives) RM461
A12: JANEZ-MRP | C12: 000035 | D12: Novo | E12: =TRUE() -> TRUE | G12: 46347 | H12: 46377 | I12: 46377 | J12: RHODIOLA DE 3% ROSAVINS 1% SALIDROSIDE (Vita Actives) RM461 | L12: 0 | M12: =FALSE() -> FALSE | N12: 75 | O12: Nabava | P12: 0002 | Q12: RHODIOLA DE 3% ROSAVINS 1% SALIDROSIDE (Vita Actives) RM461
A13: JANEZ-MRP | C13: 000036 | D13: Novo | E13: =TRUE() -> TRUE | G13: 46347 | H13: 46377 | I13: 46377 | J13: KSM-66® [Ashwagandha extract] RM1236 | L13: 0 | M13: =FALSE() -> FALSE | N13: 30 | O13: Nabava | P13: 0002 | Q13: KSM-66® [Ashwagandha extract] RM1236
A14: JANEZ-MRP | C14: 000047 | D14: Novo | E14: =TRUE() -> TRUE | G14: 46328 | H14: 46358 | I14: 46358 | J14: TeaXcel® E40 - Green tea leaf 95% polyphenols RM303 | L14: 0 | M14: =FALSE() -> FALSE | N14: 450 | O14: Nabava | P14: 0002 | Q14: TeaXcel® E40 - Green tea leaf 95% polyphenols RM303
A15: JANEZ-MRP | C15: 000049 | D15: Novo | E15: =TRUE() -> TRUE | G15: 46328 | H15: 46358 | I15: 46358 | J15: CAYENNE PEPER 10:1 (Vita Actives) RM4766 | L15: 0 | M15: =FALSE() -> FALSE | N15: 100 | O15: Nabava | P15: 0002 | Q15: CAYENNE PEPER 10:1 (Vita Actives) RM4766
... A70: JANEZ-MRP | C70: 000179 | D70: Novo | E70: =TRUE() -> TRUE | G70: 46347 | H70: 46377 | I70: 46377 | J70: Cordyceps Sinensis Extract 34-19 (Alpine) | L70: 0 | M70: =FALSE() -> FALSE | N70: 400 | O70: Nabava | P70: 0078 | Q70: Cordyceps Sinensis Extract 34-19 (Alpine)
A71: JANEZ-MRP | C71: 000182 | D71: Novo | E71: =TRUE() -> TRUE | G71: 46381 | H71: 46381 | I71: 46381 | J71: LIME POWDER FLAVOUR SD NATURAL 221620 (Frutol) | L71: 0 | M71: =FALSE() -> FALSE | N71: 125 | O71: Nabava | Q71: LIME POWDER FLAVOUR SD NATURAL 221620 (Frutol)
A72: JANEZ-MRP | C72: 000184 | D72: Novo | E72: =TRUE() -> TRUE | G72: 46378 | H72: 46378 | I72: 46378 | J72: ARTICHOKE EXTRACT 2-5% CYNARINE 88170 (Frutol) | L72: 0 | M72: =FALSE() -> FALSE | N72: 25 | O72: Nabava | Q72: ARTICHOKE EXTRACT 2-5% CYNARINE 88170 (Frutol)
A73: JANEZ-MRP | C73: 000188 | D73: Novo | E73: =TRUE() -> TRUE | G73: 46358 | H73: 46358 | I73: 46358 | J73: DANDELION ROOT 10-1 DRY EXTRACT (Alpine) | L73: 0 | M73: =FALSE() -> FALSE | N73: 50 | O73: Nabava | Q73: DANDELION ROOT 10-1 DRY EXTRACT (Alpine)
A74: JANEZ-MRP | C74: 000190 | D74: Novo | E74: =TRUE() -> TRUE | G74: 46384 | H74: 46384 | I74: 46384 | J74: Spirulina Powder 26-4 (Alpine) | L74: 0 | M74: =FALSE() -> FALSE | N74: 25 | O74: Nabava | Q74: Spirulina Powder 26-4 (Alpine)
A75: JANEZ-MRP | C75: 000191 | D75: Novo | E75: =TRUE() -> TRUE | G75: 46384 | H75: 46384 | I75: 46384 | J75: Japanese sophora extract-Quercetin 68-19 (Alpine) | L75: 0 | M75: =FALSE() -> FALSE | N75: 25 | O75: Nabava | Q75: Japanese sophora extract-Quercetin 68-19 (Alpine)
A76: JANEZ-MRP | C76: 000192 | D76: Novo | E76: =TRUE() -> TRUE | G76: 46384 | H76: 46384 | I76: 46384 | J76: Black Elderberry Extract 69-19 (Alpine) | L76: 0 | M76: =FALSE() -> FALSE | N76: 50 | O76: Nabava | Q76: Black Elderberry Extract 69-19 (Alpine)
A77: JANEZ-MRP | C77: 000193 | D77: Novo | E77: =TRUE() -> TRUE | G77: 46378 | H77: 46378 | I77: 46378 | J77: SODIUM BICARBONATE WITHOUT ACA (Palconutrifit) | L77: 0 | M77: =FALSE() -> FALSE | N77: 1100 | O77: Nabava | Q77: SODIUM BICARBONATE WITHOUT ACA (Palconutrifit)
A78: JANEZ-MRP | C78: 000195 | D78: Novo | E78: =TRUE() -> TRUE | G78: 46155 | H78: 46155 | I78: 46155 | J78: Calcium Citrat (Schmidt Pharma) | L78: 0 | M78: =FALSE() -> FALSE | N78: 375 | O78: Nabava | Q78: Calcium Citrat (Schmidt Pharma)
A79: JANEZ-MRP | B79: Attention | C79: 060000 | D79: Novo | E79: =FALSE() -> FALSE | G79: 46124 | H79: 46154 | I79: 46154 | J79: Black tea 222568 (FRUTOL) | L79: 0 | M79: =FALSE() -> FALSE | N79: 10 | O79: Nabava | P79: 0001 | Q79: Black tea 222568 (FRUTOL)
A80: JANEZ-MRP | B80: Attention | C80: 060001 | D80: Novo | E80: =FALSE() -> FALSE | G80: 46124 | H80: 46154 | I80: 46154 | J80: Lemon 220001 (FRUTOL) | L80: 0 | M80: =FALSE() -> FALSE | N80: 20 | O80: Nabava | P80: 0001 | Q80: Lemon 220001 (FRUTOL)
A81: JANEZ-MRP | B81: Attention | C81: 060002 | D81: Novo | E81: =FALSE() -> FALSE | G81: 46123 | H81: 46153 | I81: 46153 | J81: Banana (221545 (FRUTOL) | L81: 0 | M81: =FALSE() -> FALSE | N81: 10 | O81: Nabava | P81: 0001 | Q81: Banana (221545 (FRUTOL)
A82: JANEZ-MRP | B82: Attention | C82: 060003 | D82: Novo | E82: =FALSE() -> FALSE | G82: 46123 | H82: 46153 | I82: 46153 | J82: Caramel 221503 (FRUTOL) | L82: 0 | M82: =FALSE() -> FALSE | N82: 10 | O82: Nabava | P82: 0001 | Q82: Caramel 221503 (FRUTOL)
A83: JANEZ-MRP | B83: Attention | C83: 060004 | D83: Novo | E83: =FALSE() -> FALSE | G83: 46110 | H83: 46140 | I83: 46140 | J83: Peach 221549 (FRUTOL) | L83: 0 | M83: =FALSE() -> FALSE | N83: 10 | O83: Nabava | P83: 0001 | Q83: Peach 221549 (FRUTOL)
A84: JANEZ-MRP | C84: 060007 | D84: Novo | E84: =FALSE() -> FALSE | G84: 46161 | H84: 46191 | I84: 46191 | J84: Green Apple 222072 (FRTOL) | L84: 0 | M84: =FALSE() -> FALSE | N84: 10 | O84: Nabava | P84: 0001 | Q84: Green Apple 222072 (FRTOL)
A85: JANEZ-MRP | C85: 060008 | D85: Novo | E85: =FALSE() -> FALSE | G85: 46158 | H85: 46188 | I85: 46188 | J85: Lemon Lime 222180 (FRUTOL) | L85: 0 | M85: =FALSE() -> FALSE | N85: 60 | O85: Nabava | P85: 0001 | Q85: Lemon Lime 222180 (FRUTOL)
A86: JANEZ-MRP | B86: Exception | C86: 060010 | D86: Novo | E86: =FALSE() -> FALSE | G86: 46052 | H86: 46082 | I86: 46082 | J86: Apricot flavour 222074 (FRUTOL) | L86: 0 | M86: =FALSE() -> FALSE | N86: 10 | O86: Nabava | P86: 0001 | Q86: Apricot flavour 222074 (FRUTOL)
A87: JANEZ-MRP | C87: 080014 | D87: Novo | E87: =TRUE() -> TRUE | G87: 46348 | H87: 46378 | I87: 46378 | J87: Cps HX HPMC "00" transparent 105mg (ACG) | L87: 0 | M87: =FALSE() -> FALSE | N87: 1500000 | O87: Nabava | P87: 0035 | Q87: Cps HX HPMC "00" transparent 105mg (ACG)
A88: JANEZ-MRP | C88: 080016 | D88: Novo | E88: =TRUE() -> TRUE | G88: 46328 | H88: 46358 | I88: 46358 | J88: A1529 HPMC#0 98mg Capsules (Pharmavit)_new | L88: 0 | M88: =FALSE() -> FALSE | N88: 2700000 | O88: Nabava | P88: 0006 | Q88: A1529 HPMC#0 98mg Capsules (Pharmavit)_new
A89: JANEZ-MRP | C89: 080016 | D89: Novo | E89: =TRUE() -> TRUE | G89: 46348 | H89: 46378 | I89: 46378 | J89: A1529 HPMC#0 98mg Capsules (Pharmavit)_new | L89: 0 | M89: =FALSE() -> FALSE | N89: 900000 | O89: Nabava | P89: 0006 | Q89: A1529 HPMC#0 98mg Capsules (Pharmavit)_new
A90: JANEZ-MRP | C90: 080016 | D90: Novo | E90: =TRUE() -> TRUE | G90: 46354 | H90: 46384 | I90: 46384 | J90: A1529 HPMC#0 98mg Capsules (Pharmavit)_new | L90: 0 | M90: =FALSE() -> FALSE | N90: 300000 | O90: Nabava | P90: 0006 | Q90: A1529 HPMC#0 98mg Capsules (Pharmavit)_new
A91: JANEZ-MRP | C91: 080016 | D91: Novo | E91: =TRUE() -> TRUE | G91: 46355 | H91: 46385 | I91: 46385 | J91: A1529 HPMC#0 98mg Capsules (Pharmavit)_new | L91: 0 | M91: =FALSE() -> FALSE | N91: 150000 | O91: Nabava | P91: 0006 | Q91: A1529 HPMC#0 98mg Capsules (Pharmavit)_new
A92: JANEZ-MRP | C92: 080018 | D92: Novo | E92: =TRUE() -> TRUE | G92: 46322 | H92: 46352 | I92: 46352 | J92: A1528 HPMC#00 124mg Capsules (Pharmavit)_new | L92: 0 | M92: =FALSE() -> FALSE | N92: 3150000 | O92: Nabava | P92: 0006 | Q92: A1528 HPMC#00 124mg Capsules (Pharmavit)_new
A93: JANEZ-MRP | C93: 080018 | D93: Novo | E93: =TRUE() -> TRUE | G93: 46344 | H93: 46374 | I93: 46374 | J93: A1528 HPMC#00 124mg Capsules (Pharmavit)_new | L93: 0 | M93: =FALSE() -> FALSE | N93: 900000 | O93: Nabava | P93: 0006 | Q93: A1528 HPMC#00 124mg Capsules (Pharmavit)_new
A94: JANEZ-MRP | C94: 080018 | D94: Novo | E94: =TRUE() -> TRUE | G94: 46347 | H94: 46377 | I94: 46377 | J94: A1528 HPMC#00 124mg Capsules (Pharmavit)_new | L94: 0 | M94: =FALSE() -> FALSE | N94: 2550000 | O94: Nabava | P94: 0006 | Q94: A1528 HPMC#00 124mg Capsules (Pharmavit)_new
...

Sheet Preoblikovano
A1: Št. | B1: Opis | C1: Zaloga | D1: Nab. cena | E1: Količina za nabavo | F1: Nadomestek 1 - Št. | G1: Nadomestek 1 - Opis | H1: Nadomestek 1 - Zaloga | I1: Nadomestek 1 - Nab. cena | J1: Nadomestek 2 - Št. | K1: Nadomestek 2 - Opis | L1: Nadomestek 2 - Zaloga | M1: Nadomestek 2 - Nab. cena | N1: Nadomestek 3 - Št. | O1: Nadomestek 3 - Opis | P1: Nadomestek 3 - Zaloga | Q1: Nadomestek 3 - Nab. cena
A2: 2 | B2: L-Arginine hydrochloride [vegan] RM079-A (Vita Actives) | C2: 0 | D2: =IFERROR(VLOOKUP(TEXT(A2,"000000"),Artikli!$A:$K,11,FALSE),"") -> 8.75 | E2: 525 | F2: 89 | G2: AMINOFERMENT® L-Arginin HCL A0147_B (pharmavit) | H2: 793.95 | I2: =IFERROR(VLOOKUP(TEXT(F2,"000000"),Artikli!$A:$K,11,FALSE),"") -> 5.95 | M2: =IFERROR(VLOOKUP(TEXT(J2,"000000"),Artikli!$A:$K,11,FALSE),"") | Q2: =IFERROR(VLOOKUP(TEXT(N2,"000000"),Artikli!$A:$K,11,FALSE),"")
A3: 24 | B3: Magnesium Citrate Tribasic anhydrous RM450 (Vita Actives) RM450 | C3: 7.9375 | D3: =IFERROR(VLOOKUP(TEXT(A3,"000000"),Artikli!$A:$K,11,FALSE),"") -> 7.81984 | E3: 400 | F3: 7 | G3: Magnesium citrate anhydrous (HSH) | H3: 13.5 | I3: =IFERROR(VLOOKUP(TEXT(F3,"000000"),Artikli!$A:$K,11,FALSE),"") -> 6.84963 | J3: 106 | K3: A0477 Magnesium Citrate Anhydrous DC (Pharmavit) | L3: 192.39997 | M3: =IFERROR(VLOOKUP(TEXT(J3,"000000"),Artikli!$A:$K,11,FALSE),"") -> 6.95 | Q3: =IFERROR(VLOOKUP(TEXT(N3,"000000"),Artikli!$A:$K,11,FALSE),"")
A4: 25 | B4: B-Complex Capsule Premix PRM101 (VitaActives) | C4: 50 | D4: =IFERROR(VLOOKUP(TEXT(A4,"000000"),Artikli!$A:$K,11,FALSE),"") -> 40 | E4: 40 | I4: =IFERROR(VLOOKUP(TEXT(F4,"000000"),Artikli!$A:$K,11,FALSE),"") | M4: =IFERROR(VLOOKUP(TEXT(J4,"000000"),Artikli!$A:$K,11,FALSE),"") | Q4: =IFERROR(VLOOKUP(TEXT(N4,"000000"),Artikli!$A:$K,11,FALSE),"")
A5: 30 | B5: Magnesium Carbonate Heavy Powder (Vita Actives)RM1372-A | C5: 130 | D5: =IFERROR(VLOOKUP(TEXT(A5,"000000"),Artikli!$A:$K,11,FALSE),"") -> 6.6 | E5: 360 | I5: =IFERROR(VLOOKUP(TEXT(F5,"000000"),Artikli!$A:$K,11,FALSE),"") | M5: =IFERROR(VLOOKUP(TEXT(J5,"000000"),Artikli!$A:$K,11,FALSE),"") | Q5: =IFERROR(VLOOKUP(TEXT(N5,"000000"),Artikli!$A:$K,11,FALSE),"")
A6: 32 | B6: Magnesium Stearate [Vegetable] (Vita Actives)RM465 | C6: 449.775 | D6: =IFERROR(VLOOKUP(TEXT(A6,"000000"),Artikli!$A:$K,11,FALSE),"") -> 4.14 | E6: 500 | F6: 98 | G6: A0162 Magnesium Stearate (Pharmavit) | H6: 0 | I6: =IFERROR(VLOOKUP(TEXT(F6,"000000"),Artikli!$A:$K,11,FALSE),"") -> 0 | J6: 102 | K6: Mg stearate (HSH) | L6: 560.8 | M6: =IFERROR(VLOOKUP(TEXT(J6,"000000"),Artikli!$A:$K,11,FALSE),"") -> 5.45 | N6: 156 | O6: Magnesium Stearate (Vegetable) (MOSSELMAN) | P6: 3.70835 | Q6: =IFERROR(VLOOKUP(TEXT(N6,"000000"),Artikli!$A:$K,11,FALSE),"") -> 5.99527
A7: 34 | B7: D-RIBOSE (Vita Actives) RM056 | C7: 104.86 | D7: =IFERROR(VLOOKUP(TEXT(A7,"000000"),Artikli!$A:$K,11,FALSE),"") -> 13.34025 | E7: 75 | I7: =IFERROR(VLOOKUP(TEXT(F7,"000000"),Artikli!$A:$K,11,FALSE),"") | M7: =IFERROR(VLOOKUP(TEXT(J7,"000000"),Artikli!$A:$K,11,FALSE),"") | Q7: =IFERROR(VLOOKUP(TEXT(N7,"000000"),Artikli!$A:$K,11,FALSE),"")
A8: 35 | B8: RHODIOLA DE 3% ROSAVINS 1% SALIDROSIDE (Vita Actives) RM461 | C8: 283.18 | D8: =IFERROR(VLOOKUP(TEXT(A8,"000000"),Artikli!$A:$K,11,FALSE),"") -> 184 | E8: 275 | F8: 185 | G8: Val – Rhodiola Rosea - standardized extract 65-15 (3% rosavins, 1% salidroside) (AlpineGroup) | H8: 0 | I8: =IFERROR(VLOOKUP(TEXT(F8,"000000"),Artikli!$A:$K,11,FALSE),"") -> 0 | M8: =IFERROR(VLOOKUP(TEXT(J8,"000000"),Artikli!$A:$K,11,FALSE),"") | Q8: =IFERROR(VLOOKUP(TEXT(N8,"000000"),Artikli!$A:$K,11,FALSE),"")
A9: 36 | B9: KSM-66® [Ashwagandha extract] RM1236 | C9: 112 | D9: =IFERROR(VLOOKUP(TEXT(A9,"000000"),Artikli!$A:$K,11,FALSE),"") -> 74.5 | E9: 30 | I9: =IFERROR(VLOOKUP(TEXT(F9,"000000"),Artikli!$A:$K,11,FALSE),"") | M9: =IFERROR(VLOOKUP(TEXT(J9,"000000"),Artikli!$A:$K,11,FALSE),"") | Q9: =IFERROR(VLOOKUP(TEXT(N9,"000000"),Artikli!$A:$K,11,FALSE),"")
A10: 47 | B10: TeaXcel® E40 - Green tea leaf 95% polyphenols RM303 | C10: 457 | D10: =IFERROR(VLOOKUP(TEXT(A10,"000000"),Artikli!$A:$K,11,FALSE),"") -> 26.6 | E10: 450 | I10: =IFERROR(VLOOKUP(TEXT(F10,"000000"),Artikli!$A:$K,11,FALSE),"") | M10: =IFERROR(VLOOKUP(TEXT(J10,"000000"),Artikli!$A:$K,11,FALSE),"") | Q10: =IFERROR(VLOOKUP(TEXT(N10,"000000"),Artikli!$A:$K,11,FALSE),"")
A11: 49 | B11: CAYENNE PEPER 10:1 (Vita Actives) RM4766 | C11: 101 | D11: =IFERROR(VLOOKUP(TEXT(A11,"000000"),Artikli!$A:$K,11,FALSE),"") -> 22.76 | E11: 100 | I11: =IFERROR(VLOOKUP(TEXT(F11,"000000"),Artikli!$A:$K,11,FALSE),"") | M11: =IFERROR(VLOOKUP(TEXT(J11,"000000"),Artikli!$A:$K,11,FALSE),"") | Q11: =IFERROR(VLOOKUP(TEXT(N11,"000000"),Artikli!$A:$K,11,FALSE),"")
A12: 51 | B12: Grape Seed Extract GSE (Vita Actives) RM4160 | C12: 100 | D12: =IFERROR(VLOOKUP(TEXT(A12,"000000"),Artikli!$A:$K,11,FALSE),"") -> 22.7 | E12: 100 | I12: =IFERROR(VLOOKUP(TEXT(F12,"000000"),Artikli!$A:$K,11,FALSE),"") | M12: =IFERROR(VLOOKUP(TEXT(J12,"000000"),Artikli!$A:$K,11,FALSE),"") | Q12: =IFERROR(VLOOKUP(TEXT(N12,"000000"),Artikli!$A:$K,11,FALSE),"")
A13: 53 | B13: Caffeine Anhydrous powder (Vita Actives) RM017 | C13: 111.25 | D13: =IFERROR(VLOOKUP(TEXT(A13,"000000"),Artikli!$A:$K,11,FALSE),"") -> 11.76 | E13: 50 | F13: 112 | G13: A1145 Caffein Anhydrous (Pharmavit) | H13: 0 | I13: =IFERROR(VLOOKUP(TEXT(F13,"000000"),Artikli!$A:$K,11,FALSE),"") -> 0 | M13: =IFERROR(VLOOKUP(TEXT(J13,"000000"),Artikli!$A:$K,11,FALSE),"") | Q13: =IFERROR(VLOOKUP(TEXT(N13,"000000"),Artikli!$A:$K,11,FALSE),"")
A14: 55 | B14: Magnesium Oxide DC Granular RM118B (Vita Actives) | C14: 0 | D14: =IFERROR(VLOOKUP(TEXT(A14,"000000"),Artikli!$A:$K,11,FALSE),"") -> 7.75158 | E14: 1500 | F14: 107 | G14: A0161 Magnesium Oxide DC (Pharmavit) | H14: 405.05 | I14: =IFERROR(VLOOKUP(TEXT(F14,"000000"),Artikli!$A:$K,11,FALSE),"") -> 5.65 | M14: =IFERROR(VLOOKUP(TEXT(J14,"000000"),Artikli!$A:$K,11,FALSE),"") | Q14: =IFERROR(VLOOKUP(TEXT(N14,"000000"),Artikli!$A:$K,11,FALSE),"")
A15: 56 | B15: Isomaltulose Powder RM1501 (Vita Actives) | C15: 25.00174 | D15: =IFERROR(VLOOKUP(TEXT(A15,"000000"),Artikli!$A:$K,11,FALSE),"") -> 6.97 | E15: 25 | I15: =IFERROR(VLOOKUP(TEXT(F15,"000000"),Artikli!$A:$K,11,FALSE),"") | M15: =IFERROR(VLOOKUP(TEXT(J15,"000000"),Artikli!$A:$K,11,FALSE),"") | Q15: =IFERROR(VLOOKUP(TEXT(N15,"000000"),Artikli!$A:$K,11,FALSE),"")
A16: 60 | B16: Citric Acid Anhydrous (Pharmavit) | C16: 0 | D16: =IFERROR(VLOOKUP(TEXT(A16,"000000"),Artikli!$A:$K,11,FALSE),"") -> 3.95059 | E16: 50 | I16: =IFERROR(VLOOKUP(TEXT(F16,"000000"),Artikli!$A:$K,11,FALSE),"") | M16: =IFERROR(VLOOKUP(TEXT(J16,"000000"),Artikli!$A:$K,11,FALSE),"") | Q16: =IFERROR(VLOOKUP(TEXT(N16,"000000"),Artikli!$A:$K,11,FALSE),"")
A17: 61 | B17: Calcium pyruvate powder RM730 (VitaActives) | C17: 79.86 | D17: =IFERROR(VLOOKUP(TEXT(A17,"000000"),Artikli!$A:$K,11,FALSE),"") -> 16.82016 | E17: 75 | I17: =IFERROR(VLOOKUP(TEXT(F17,"000000"),Artikli!$A:$K,11,FALSE),"") | M17: =IFERROR(VLOOKUP(TEXT(J17,"000000"),Artikli!$A:$K,11,FALSE),"") | Q17: =IFERROR(VLOOKUP(TEXT(N17,"000000"),Artikli!$A:$K,11,FALSE),"")
A18: 63 | B18: GINSENG EXTRACT 80% RM 713 (VitaActives) | C18: 24 | D18: =IFERROR(VLOOKUP(TEXT(A18,"000000"),Artikli!$A:$K,11,FALSE),"") -> 27 | E18: 25 | I18: =IFERROR(VLOOKUP(TEXT(F18,"000000"),Artikli!$A:$K,11,FALSE),"") | M18: =IFERROR(VLOOKUP(TEXT(J18,"000000"),Artikli!$A:$K,11,FALSE),"") | Q18: =IFERROR(VLOOKUP(TEXT(N18,"000000"),Artikli!$A:$K,11,FALSE),"")
A19: 68 | B19: 00123 Cordyceps 7% Cordiceptic Acid extract powder (Alpine Nutrition) | C19: 4 | D19: =IFERROR(VLOOKUP(TEXT(A19,"000000"),Artikli!$A:$K,11,FALSE),"") -> 30.3 | E19: 10 | F19: 179 | G19: Cordyceps Sinensis Extract 64-20 (Alpine) | H19: 361 | I19: =IFERROR(VLOOKUP(TEXT(F19,"000000"),Artikli!$A:$K,11,FALSE),"") -> 0 | M19: =IFERROR(VLOOKUP(TEXT(J19,"000000"),Artikli!$A:$K,11,FALSE),"") | Q19: =IFERROR(VLOOKUP(TEXT(N19,"000000"),Artikli!$A:$K,11,FALSE),"")
A20: 71 | B20: Creatine HCL hydrochloride RM 032 (VitaActives) | C20: 465 | D20: =IFERROR(VLOOKUP(TEXT(A20,"000000"),Artikli!$A:$K,11,FALSE),"") -> 7.6 | E20: 900 | I20: =IFERROR(VLOOKUP(TEXT(F20,"000000"),Artikli!$A:$K,11,FALSE),"") | M20: =IFERROR(VLOOKUP(TEXT(J20,"000000"),Artikli!$A:$K,11,FALSE),"") | Q20: =IFERROR(VLOOKUP(TEXT(N20,"000000"),Artikli!$A:$K,11,FALSE),"")
A21: 72 | B21: Beta Vulgaris extract 10:1 (Vita Actives) RM4790 | C21: 56.25 | D21: =IFERROR(VLOOKUP(TEXT(A21,"000000"),Artikli!$A:$K,11,FALSE),"") -> 21 | E21: 600 | I21: =IFERROR(VLOOKUP(TEXT(F21,"000000"),Artikli!$A:$K,11,FALSE),"") | M21: =IFERROR(VLOOKUP(TEXT(J21,"000000"),Artikli!$A:$K,11,FALSE),"") | Q21: =IFERROR(VLOOKUP(TEXT(N21,"000000"),Artikli!$A:$K,11,FALSE),"")
A22: 73 | B22: Red spinach extract (9% Nitrate conc.) (Vita Actives) RM4560 | C22: 265.7482 | D22: =IFERROR(VLOOKUP(TEXT(A22,"000000"),Artikli!$A:$K,11,FALSE),"") -> 82.84999 | E22: 375 | I22: =IFERROR(VLOOKUP(TEXT(F22,"000000"),Artikli!$A:$K,11,FALSE),"") | M22: =IFERROR(VLOOKUP(TEXT(J22,"000000"),Artikli!$A:$K,11,FALSE),"") | Q22: =IFERROR(VLOOKUP(TEXT(N22,"000000"),Artikli!$A:$K,11,FALSE),"")
A23: 74 | B23: Arugula extract 10:1 (Vita Actives) RM4783 | C23: 0 | D23: =IFERROR(VLOOKUP(TEXT(A23,"000000"),Artikli!$A:$K,11,FALSE),"") -> 38 | E23: 275 | F23: 121 | G23: Arugula extract 10:1 Alpine Nutrition | H23: 253.125 | I23: =IFERROR(VLOOKUP(TEXT(F23,"000000"),Artikli!$A:$K,11,FALSE),"") -> 34 | M23: =IFERROR(VLOOKUP(TEXT(J23,"000000"),Artikli!$A:$K,11,FALSE),"") | Q23: =IFERROR(VLOOKUP(TEXT(N23,"000000"),Artikli!$A:$K,11,FALSE),"")
A24: 76 | B24: L-Carnitin-L-Tartrate (Pharmavit) A0531 | C24: 17.5 | D24: =IFERROR(VLOOKUP(TEXT(A24,"000000"),Artikli!$A:$K,11,FALSE),"") -> 21.44971 | E24: 675 | I24: =IFERROR(VLOOKUP(TEXT(F24,"000000"),Artikli!$A:$K,11,FALSE),"") | M24: =IFERROR(VLOOKUP(TEXT(J24,"000000"),Artikli!$A:$K,11,FALSE),"") | Q24: =IFERROR(VLOOKUP(TEXT(N24,"000000"),Artikli!$A:$K,11,FALSE),"")
A25: 77 | B25: A1399 N-Acetyl-L-Carnitin (Pharmavit) A1399 | C25: 0 | D25: =IFERROR(VLOOKUP(TEXT(A25,"000000"),Artikli!$A:$K,11,FALSE),"") -> 25.14971 | E25: 175 | I25: =IFERROR(VLOOKUP(TEXT(F25,"000000"),Artikli!$A:$K,11,FALSE),"") | M25: =IFERROR(VLOOKUP(TEXT(J25,"000000"),Artikli!$A:$K,11,FALSE),"") | Q25: =IFERROR(VLOOKUP(TEXT(N25,"000000"),Artikli!$A:$K,11,FALSE),"")
A26: 78 | B26: Bearberry [Arctostaphylos uva-ursi] leaf 20% Arbutin [HPLC] powder extract (RM4422) | C26: 108 | D26: =IFERROR(VLOOKUP(TEXT(A26,"000000"),Artikli!$A:$K,11,FALSE),"") -> 56 | E26: 25 | I26: =IFERROR(VLOOKUP(TEXT(F26,"000000"),Artikli!$A:$K,11,FALSE),"") | M26: =IFERROR(VLOOKUP(TEXT(J26,"000000"),Artikli!$A:$K,11,FALSE),"") | Q26: =IFERROR(VLOOKUP(TEXT(N26,"000000"),Artikli!$A:$K,11,FALSE),"")
A27: 79 | B27: Dandelion [Taraxacum officinale] root 2% Flavones [UV] powder extract (5 to 1) (RM1378) | C27: 118.5 | D27: =IFERROR(VLOOKUP(TEXT(A27,"000000"),Artikli!$A:$K,11,FALSE),"") -> 22.92 | E27: 25 | F27: 52 | G27: DANDELION ROOT 10-1 DRY EXTRAC (Vita Actives) RM4770 | H27: 3 | I27: =IFERROR(VLOOKUP(TEXT(F27,"000000"),Artikli!$A:$K,11,FALSE),"") -> 25.5 | M27: =IFERROR(VLOOKUP(TEXT(J27,"000000"),Artikli!$A:$K,11,FALSE),"") | Q27: =IFERROR(VLOOKUP(TEXT(N27,"000000"),Artikli!$A:$K,11,FALSE),"")
A28: 80 | B28: Parsley [Petroselinum crispum] herb 10 to 1 powder extract (RM4626) | C28: 79 | D28: =IFERROR(VLOOKUP(TEXT(A28,"000000"),Artikli!$A:$K,11,FALSE),"") -> 23.6 | E28: 25 | F28: 150 | G28: Parsley [Petroselinum crispum] herb 10 to 1 powder extract RM4626 (VitaActives) | H28: 24.134 | I28: =IFERROR(VLOOKUP(TEXT(F28,"000000"),Artikli!$A:$K,11,FALSE),"") -> 23.6 | M28: =IFERROR(VLOOKUP(TEXT(J28,"000000"),Artikli!$A:$K,11,FALSE),"") | Q28: =IFERROR(VLOOKUP(TEXT(N28,"000000"),Artikli!$A:$K,11,FALSE),"")
A29: 82 | B29: Artichoke [Cynara scolymus L] leaf 5% Cynarin [UV] powder extract (RM1293) | C29: 54 | D29: =IFERROR(VLOOKUP(TEXT(A29,"000000"),Artikli!$A:$K,11,FALSE),"") -> 62.25 | E29: 25 | F29: 184 | G29: ARTICHOKE EXTRACT 2-5% CYNARINE 88170 (Frutol) | H29: 50 | I29: =IFERROR(VLOOKUP(TEXT(F29,"000000"),Artikli!$A:$K,11,FALSE),"") -> 28 | M29: =IFERROR(VLOOKUP(TEXT(J29,"000000"),Artikli!$A:$K,11,FALSE),"") | Q29: =IFERROR(VLOOKUP(TEXT(N29,"000000"),Artikli!$A:$K,11,FALSE),"")
A30: 83 | B30: Pyridoxine hydrochloride powder [Vitamin B6] RM135 (VitaActives) | C30: 8.9 | D30: =IFERROR(VLOOKUP(TEXT(A30,"000000"),Artikli!$A:$K,11,FALSE),"") -> 46 | E30: 25 | I30: =IFERROR(VLOOKUP(TEXT(F30,"000000"),Artikli!$A:$K,11,FALSE),"") | M30: =IFERROR(VLOOKUP(TEXT(J30,"000000"),Artikli!$A:$K,11,FALSE),"") | Q30: =IFERROR(VLOOKUP(TEXT(N30,"000000"),Artikli!$A:$K,11,FALSE),"")
A31: 84 | B31: TriPotassium Citrate anhydrous powder RM2042 (VitaActives) | C31: 231.34 | D31: =IFERROR(VLOOKUP(TEXT(A31,"000000"),Artikli!$A:$K,11,FALSE),"") -> 4.92798 | E31: 150 | F31: 41 | G31: Tripotassium Citrate Monohydrate (Vita Actives) RM325A | H31: 25 | I31: =IFERROR(VLOOKUP(TEXT(F31,"000000"),Artikli!$A:$K,11,FALSE),"") -> 3.33955 | J31: 120 | K31: Tripotassium Citrate Monohydrate Fine (Lehvoss DE) | L31: 5 | M31: =IFERROR(VLOOKUP(TEXT(J31,"000000"),Artikli!$A:$K,11,FALSE),"") -> 10.284 | Q31: =IFERROR(VLOOKUP(TEXT(N31,"000000"),Artikli!$A:$K,11,FALSE),"")
A32: 104 | B32: Magnesium citrate buffered [30% Mg] powder RM2006 (VitaActives) | C32: 35 | D32: =IFERROR(VLOOKUP(TEXT(A32,"000000"),Artikli!$A:$K,11,FALSE),"") -> 5.5 | E32: 50 | I32: =IFERROR(VLOOKUP(TEXT(F32,"000000"),Artikli!$A:$K,11,FALSE),"") | M32: =IFERROR(VLOOKUP(TEXT(J32,"000000"),Artikli!$A:$K,11,FALSE),"") | Q32: =IFERROR(VLOOKUP(TEXT(N32,"000000"),Artikli!$A:$K,11,FALSE),"")
A33: 105 | B33: A1306_B AMINOFERMENT® Beta Alanin (Pharmavit) | C33: 650 | D33: =IFERROR(VLOOKUP(TEXT(A33,"000000"),Artikli!$A:$K,11,FALSE),"") -> 2.85 | E33: 775 | F33: 33 | G33: BETA-ALANINE [VEGAN](Vita Actives) RM007B | H33: 20 | I33: =IFERROR(VLOOKUP(TEXT(F33,"000000"),Artikli!$A:$K,11,FALSE),"") -> 2.94 | M33: =IFERROR(VLOOKUP(TEXT(J33,"000000"),Artikli!$A:$K,11,FALSE),"") | Q33: =IFERROR(VLOOKUP(TEXT(N33,"000000"),Artikli!$A:$K,11,FALSE),"")
A34: 116 | B34: Senactiv (HSH) | C34: 24 | D34: =IFERROR(VLOOKUP(TEXT(A34,"000000"),Artikli!$A:$K,11,FALSE),"") -> 640 | E34: 25 | F34: 62 | G34: Senactiv® (JDS) | H34: 0 | I34: =IFERROR(VLOOKUP(TEXT(F34,"000000"),Artikli!$A:$K,11,FALSE),"") -> 605.773 | M34: =IFERROR(VLOOKUP(TEXT(J34,"000000"),Artikli!$A:$K,11,FALSE),"") | Q34: =IFERROR(VLOOKUP(TEXT(N34,"000000"),Artikli!$A:$K,11,FALSE),"")
A35: 127 | B35: Cholecalciferol [100,000 IU per g [0.25% D3]] powder RM159-B (VitaActives) - Vitamin D3 | C35: 25 | D35: =IFERROR(VLOOKUP(TEXT(A35,"000000"),Artikli!$A:$K,11,FALSE),"") -> 15.2 | E35: 25 | I35: =IFERROR(VLOOKUP(TEXT(F35,"000000"),Artikli!$A:$K,11,FALSE),"") | M35: =IFERROR(VLOOKUP(TEXT(J35,"000000"),Artikli!$A:$K,11,FALSE),"") | Q35: =IFERROR(VLOOKUP(TEXT(N35,"000000"),Artikli!$A:$K,11,FALSE),"")
A36: 131 | B36: L-ORNITHINE HCL - O1063201 (AlpineGroup) | C36: 75 | D36: =IFERROR(VLOOKUP(TEXT(A36,"000000"),Artikli!$A:$K,11,FALSE),"") -> 15.9 | E36: 125 | I36: =IFERROR(VLOOKUP(TEXT(F36,"000000"),Artikli!$A:$K,11,FALSE),"") | M36: =IFERROR(VLOOKUP(TEXT(J36,"000000"),Artikli!$A:$K,11,FALSE),"") | Q36: =IFERROR(VLOOKUP(TEXT(N36,"000000"),Artikli!$A:$K,11,FALSE),"")
A37: 138 | B37: Fructo-oligosaccharides [FOS] Powder [Low aw] [Source: Sugarcane] (RM1525-A) VitaActives | C37: 182.78 | D37: =IFERROR(VLOOKUP(TEXT(A37,"000000"),Artikli!$A:$K,11,FALSE),"") -> 8.52 | E37: 75 | I37: =IFERROR(VLOOKUP(TEXT(F37,"000000"),Artikli!$A:$K,11,FALSE),"") | M37: =IFERROR(VLOOKUP(TEXT(J37,"000000"),Artikli!$A:$K,11,FALSE),"") | Q37: =IFERROR(VLOOKUP(TEXT(N37,"000000"),Artikli!$A:$K,11,FALSE),"")
A38: 139 | B38: Art. 849FRF – exGrape™ SEED OPCFR Grape Seed Extract (Breko) | C38: 52.63142 | D38: =IFERROR(VLOOKUP(TEXT(A38,"000000"),Artikli!$A:$K,11,FALSE),"") -> 66.66971 | E38: 25 | I38: =IFERROR(VLOOKUP(TEXT(F38,"000000"),Artikli!$A:$K,11,FALSE),"") | M38: =IFERROR(VLOOKUP(TEXT(J38,"000000"),Artikli!$A:$K,11,FALSE),"") | Q38: =IFERROR(VLOOKUP(TEXT(N38,"000000"),Artikli!$A:$K,11,FALSE),"")
A39: 143 | B39: Glucomannan 95% [Ex- Amorphophallus konjac] RM1285 (VitaActives) | C39: 237 | D39: =IFERROR(VLOOKUP(TEXT(A39,"000000"),Artikli!$A:$K,11,FALSE),"") -> 20.1 | E39: 25 | I39: =IFERROR(VLOOKUP(TEXT(F39,"000000"),Artikli!$A:$K,11,FALSE),"") | M39: =IFERROR(VLOOKUP(TEXT(J39,"000000"),Artikli!$A:$K,11,FALSE),"") | Q39: =IFERROR(VLOOKUP(TEXT(N39,"000000"),Artikli!$A:$K,11,FALSE),"")
A40: 145 | B40: L-Tyrosine powder [Vegan] RM563 (VitaActives) | C40: 67.2 | D40: =IFERROR(VLOOKUP(TEXT(A40,"000000"),Artikli!$A:$K,11,FALSE),"") -> 7.25 | E40: 150 | I40: =IFERROR(VLOOKUP(TEXT(F40,"000000"),Artikli!$A:$K,11,FALSE),"") | M40: =IFERROR(VLOOKUP(TEXT(J40,"000000"),Artikli!$A:$K,11,FALSE),"") | Q40: =IFERROR(VLOOKUP(TEXT(N40,"000000"),Artikli!$A:$K,11,FALSE),"")
...

Sheet List2
